ERROR 2020-11-04 21:18:28,076 basehttp 124 "GET /admin/home/banner/3/update/ HTTP/1.1" 500 59
ERROR 2020-11-04 21:19:08,949 basehttp 124 "GET /admin/home/banner/3/update/ HTTP/1.1" 500 59
ERROR 2020-11-04 21:44:48,496 basehttp 124 "GET /admin/home/nav/ HTTP/1.1" 500 59
ERROR 2020-11-04 21:47:18,970 basehttp 124 "GET /admin/home/nav/ HTTP/1.1" 500 59
ERROR 2020-11-04 21:50:08,542 basehttp 124 "GET /admin/home/nav/add/ HTTP/1.1" 500 59
ERROR 2020-11-05 08:31:20,747 basehttp 124 "POST /admin/home/nav/add/ HTTP/1.1" 500 59
ERROR 2020-11-05 10:30:53,839 exception 118 Internal Server Error: /home/header/
Traceback (most recent call last):
  File "F:\virtual\demo\lib\site-packages\django\db\backends\utils.py", line 85, in _execute
    return self.cursor.execute(sql, params)
  File "F:\virtual\demo\lib\site-packages\django\db\backends\mysql\base.py", line 71, in execute
    return self.cursor.execute(query, args)
  File "F:\virtual\demo\lib\site-packages\MySQLdb\cursors.py", line 206, in execute
    res = self._query(query)
  File "F:\virtual\demo\lib\site-packages\MySQLdb\cursors.py", line 319, in _query
    db.query(q)
  File "F:\virtual\demo\lib\site-packages\MySQLdb\connections.py", line 259, in query
    _mysql.connection.query(self, query)
MySQLdb._exceptions.OperationalError: (1054, "Unknown column 'nav.id' in 'field list'")

The above exception was the direct cause of the following exception:

Traceback (most recent call last):
  File "F:\virtual\demo\lib\site-packages\rest_framework\views.py", line 494, in dispatch
    response = handler(request, *args, **kwargs)
  File "F:\virtual\demo\lib\site-packages\rest_framework\generics.py", line 199, in get
    return self.list(request, *args, **kwargs)
  File "F:\virtual\demo\lib\site-packages\rest_framework\mixins.py", line 46, in list
    return Response(serializer.data)
  File "F:\virtual\demo\lib\site-packages\rest_framework\serializers.py", line 757, in data
    ret = super().data
  File "F:\virtual\demo\lib\site-packages\rest_framework\serializers.py", line 261, in data
    self._data = self.to_representation(self.instance)
  File "F:\virtual\demo\lib\site-packages\rest_framework\serializers.py", line 675, in to_representation
    self.child.to_representation(item) for item in iterable
  File "F:\virtual\demo\lib\site-packages\django\db\models\query.py", line 272, in __iter__
    self._fetch_all()
  File "F:\virtual\demo\lib\site-packages\django\db\models\query.py", line 1179, in _fetch_all
    self._result_cache = list(self._iterable_class(self))
  File "F:\virtual\demo\lib\site-packages\django\db\models\query.py", line 53, in __iter__
    results = compiler.execute_sql(chunked_fetch=self.chunked_fetch, chunk_size=self.chunk_size)
  File "F:\virtual\demo\lib\site-packages\django\db\models\sql\compiler.py", line 1068, in execute_sql
    cursor.execute(sql, params)
  File "F:\virtual\demo\lib\site-packages\django\db\backends\utils.py", line 100, in execute
    return super().execute(sql, params)
  File "F:\virtual\demo\lib\site-packages\django\db\backends\utils.py", line 68, in execute
    return self._execute_with_wrappers(sql, params, many=False, executor=self._execute)
  File "F:\virtual\demo\lib\site-packages\django\db\backends\utils.py", line 77, in _execute_with_wrappers
    return executor(sql, params, many, context)
  File "F:\virtual\demo\lib\site-packages\django\db\backends\utils.py", line 85, in _execute
    return self.cursor.execute(sql, params)
  File "F:\virtual\demo\lib\site-packages\django\db\utils.py", line 89, in __exit__
    raise dj_exc_value.with_traceback(traceback) from exc_value
  File "F:\virtual\demo\lib\site-packages\django\db\backends\utils.py", line 85, in _execute
    return self.cursor.execute(sql, params)
  File "F:\virtual\demo\lib\site-packages\django\db\backends\mysql\base.py", line 71, in execute
    return self.cursor.execute(query, args)
  File "F:\virtual\demo\lib\site-packages\MySQLdb\cursors.py", line 206, in execute
    res = self._query(query)
  File "F:\virtual\demo\lib\site-packages\MySQLdb\cursors.py", line 319, in _query
    db.query(q)
  File "F:\virtual\demo\lib\site-packages\MySQLdb\connections.py", line 259, in query
    _mysql.connection.query(self, query)
django.db.utils.OperationalError: (1054, "Unknown column 'nav.id' in 'field list'")

During handling of the above exception, another exception occurred:

Traceback (most recent call last):
  File "F:\virtual\demo\lib\site-packages\rest_framework\settings.py", line 177, in import_from_string
    return import_string(val)
  File "F:\virtual\demo\lib\site-packages\django\utils\module_loading.py", line 17, in import_string
    module = import_module(module_path)
  File "c:\python36\lib\importlib\__init__.py", line 126, in import_module
    return _bootstrap._gcd_import(name[level:], package, level)
  File "<frozen importlib._bootstrap>", line 994, in _gcd_import
  File "<frozen importlib._bootstrap>", line 971, in _find_and_load
  File "<frozen importlib._bootstrap>", line 941, in _find_and_load_unlocked
  File "<frozen importlib._bootstrap>", line 219, in _call_with_frames_removed
  File "<frozen importlib._bootstrap>", line 994, in _gcd_import
  File "<frozen importlib._bootstrap>", line 971, in _find_and_load
  File "<frozen importlib._bootstrap>", line 953, in _find_and_load_unlocked
ModuleNotFoundError: No module named 'drf_day4'

During handling of the above exception, another exception occurred:

Traceback (most recent call last):
  File "F:\virtual\demo\lib\site-packages\django\core\handlers\exception.py", line 35, in inner
    response = get_response(request)
  File "F:\virtual\demo\lib\site-packages\django\core\handlers\base.py", line 128, in _get_response
    response = self.process_exception_by_middleware(e, request)
  File "F:\virtual\demo\lib\site-packages\django\core\handlers\base.py", line 126, in _get_response
    response = wrapped_callback(request, *callback_args, **callback_kwargs)
  File "F:\virtual\demo\lib\site-packages\django\views\decorators\csrf.py", line 54, in wrapped_view
    return view_func(*args, **kwargs)
  File "F:\virtual\demo\lib\site-packages\django\views\generic\base.py", line 69, in view
    return self.dispatch(request, *args, **kwargs)
  File "F:\virtual\demo\lib\site-packages\rest_framework\views.py", line 497, in dispatch
    response = self.handle_exception(exc)
  File "F:\virtual\demo\lib\site-packages\rest_framework\views.py", line 451, in handle_exception
    exception_handler = self.get_exception_handler()
  File "F:\virtual\demo\lib\site-packages\rest_framework\views.py", line 298, in get_exception_handler
    return self.settings.EXCEPTION_HANDLER
  File "F:\virtual\demo\lib\site-packages\rest_framework\settings.py", line 220, in __getattr__
    val = perform_import(val, attr)
  File "F:\virtual\demo\lib\site-packages\rest_framework\settings.py", line 166, in perform_import
    return import_from_string(val, setting_name)
  File "F:\virtual\demo\lib\site-packages\rest_framework\settings.py", line 180, in import_from_string
    raise ImportError(msg)
ImportError: Could not import 'drf_day4.exceptions.exception_handler' for API setting 'EXCEPTION_HANDLER'. ModuleNotFoundError: No module named 'drf_day4'.
ERROR 2020-11-05 10:30:53,840 exception 118 Internal Server Error: /home/banner/
Traceback (most recent call last):
  File "F:\virtual\demo\lib\site-packages\django\db\backends\utils.py", line 85, in _execute
    return self.cursor.execute(sql, params)
  File "F:\virtual\demo\lib\site-packages\django\db\backends\mysql\base.py", line 71, in execute
    return self.cursor.execute(query, args)
  File "F:\virtual\demo\lib\site-packages\MySQLdb\cursors.py", line 206, in execute
    res = self._query(query)
  File "F:\virtual\demo\lib\site-packages\MySQLdb\cursors.py", line 319, in _query
    db.query(q)
  File "F:\virtual\demo\lib\site-packages\MySQLdb\connections.py", line 259, in query
    _mysql.connection.query(self, query)
MySQLdb._exceptions.OperationalError: (1054, "Unknown column 'banner.id' in 'field list'")

The above exception was the direct cause of the following exception:

Traceback (most recent call last):
  File "F:\virtual\demo\lib\site-packages\rest_framework\views.py", line 494, in dispatch
    response = handler(request, *args, **kwargs)
  File "F:\virtual\demo\lib\site-packages\rest_framework\generics.py", line 199, in get
    return self.list(request, *args, **kwargs)
  File "F:\virtual\demo\lib\site-packages\rest_framework\mixins.py", line 46, in list
    return Response(serializer.data)
  File "F:\virtual\demo\lib\site-packages\rest_framework\serializers.py", line 757, in data
    ret = super().data
  File "F:\virtual\demo\lib\site-packages\rest_framework\serializers.py", line 261, in data
    self._data = self.to_representation(self.instance)
  File "F:\virtual\demo\lib\site-packages\rest_framework\serializers.py", line 675, in to_representation
    self.child.to_representation(item) for item in iterable
  File "F:\virtual\demo\lib\site-packages\django\db\models\query.py", line 272, in __iter__
    self._fetch_all()
  File "F:\virtual\demo\lib\site-packages\django\db\models\query.py", line 1179, in _fetch_all
    self._result_cache = list(self._iterable_class(self))
  File "F:\virtual\demo\lib\site-packages\django\db\models\query.py", line 53, in __iter__
    results = compiler.execute_sql(chunked_fetch=self.chunked_fetch, chunk_size=self.chunk_size)
  File "F:\virtual\demo\lib\site-packages\django\db\models\sql\compiler.py", line 1068, in execute_sql
    cursor.execute(sql, params)
  File "F:\virtual\demo\lib\site-packages\django\db\backends\utils.py", line 100, in execute
    return super().execute(sql, params)
  File "F:\virtual\demo\lib\site-packages\django\db\backends\utils.py", line 68, in execute
    return self._execute_with_wrappers(sql, params, many=False, executor=self._execute)
  File "F:\virtual\demo\lib\site-packages\django\db\backends\utils.py", line 77, in _execute_with_wrappers
    return executor(sql, params, many, context)
  File "F:\virtual\demo\lib\site-packages\django\db\backends\utils.py", line 85, in _execute
    return self.cursor.execute(sql, params)
  File "F:\virtual\demo\lib\site-packages\django\db\utils.py", line 89, in __exit__
    raise dj_exc_value.with_traceback(traceback) from exc_value
  File "F:\virtual\demo\lib\site-packages\django\db\backends\utils.py", line 85, in _execute
    return self.cursor.execute(sql, params)
  File "F:\virtual\demo\lib\site-packages\django\db\backends\mysql\base.py", line 71, in execute
    return self.cursor.execute(query, args)
  File "F:\virtual\demo\lib\site-packages\MySQLdb\cursors.py", line 206, in execute
    res = self._query(query)
  File "F:\virtual\demo\lib\site-packages\MySQLdb\cursors.py", line 319, in _query
    db.query(q)
  File "F:\virtual\demo\lib\site-packages\MySQLdb\connections.py", line 259, in query
    _mysql.connection.query(self, query)
django.db.utils.OperationalError: (1054, "Unknown column 'banner.id' in 'field list'")

During handling of the above exception, another exception occurred:

Traceback (most recent call last):
  File "F:\virtual\demo\lib\site-packages\rest_framework\settings.py", line 177, in import_from_string
    return import_string(val)
  File "F:\virtual\demo\lib\site-packages\django\utils\module_loading.py", line 17, in import_string
    module = import_module(module_path)
  File "c:\python36\lib\importlib\__init__.py", line 126, in import_module
    return _bootstrap._gcd_import(name[level:], package, level)
  File "<frozen importlib._bootstrap>", line 994, in _gcd_import
  File "<frozen importlib._bootstrap>", line 971, in _find_and_load
  File "<frozen importlib._bootstrap>", line 941, in _find_and_load_unlocked
  File "<frozen importlib._bootstrap>", line 219, in _call_with_frames_removed
  File "<frozen importlib._bootstrap>", line 994, in _gcd_import
  File "<frozen importlib._bootstrap>", line 971, in _find_and_load
  File "<frozen importlib._bootstrap>", line 953, in _find_and_load_unlocked
ModuleNotFoundError: No module named 'drf_day4'

During handling of the above exception, another exception occurred:

Traceback (most recent call last):
  File "F:\virtual\demo\lib\site-packages\django\core\handlers\exception.py", line 35, in inner
    response = get_response(request)
  File "F:\virtual\demo\lib\site-packages\django\core\handlers\base.py", line 128, in _get_response
    response = self.process_exception_by_middleware(e, request)
  File "F:\virtual\demo\lib\site-packages\django\core\handlers\base.py", line 126, in _get_response
    response = wrapped_callback(request, *callback_args, **callback_kwargs)
  File "F:\virtual\demo\lib\site-packages\django\views\decorators\csrf.py", line 54, in wrapped_view
    return view_func(*args, **kwargs)
  File "F:\virtual\demo\lib\site-packages\django\views\generic\base.py", line 69, in view
    return self.dispatch(request, *args, **kwargs)
  File "F:\virtual\demo\lib\site-packages\rest_framework\views.py", line 497, in dispatch
    response = self.handle_exception(exc)
  File "F:\virtual\demo\lib\site-packages\rest_framework\views.py", line 451, in handle_exception
    exception_handler = self.get_exception_handler()
  File "F:\virtual\demo\lib\site-packages\rest_framework\views.py", line 298, in get_exception_handler
    return self.settings.EXCEPTION_HANDLER
  File "F:\virtual\demo\lib\site-packages\rest_framework\settings.py", line 220, in __getattr__
    val = perform_import(val, attr)
  File "F:\virtual\demo\lib\site-packages\rest_framework\settings.py", line 166, in perform_import
    return import_from_string(val, setting_name)
  File "F:\virtual\demo\lib\site-packages\rest_framework\settings.py", line 180, in import_from_string
    raise ImportError(msg)
ImportError: Could not import 'drf_day4.exceptions.exception_handler' for API setting 'EXCEPTION_HANDLER'. ModuleNotFoundError: No module named 'drf_day4'.
ERROR 2020-11-05 10:30:53,842 exception 118 Internal Server Error: /home/footer/
Traceback (most recent call last):
  File "F:\virtual\demo\lib\site-packages\django\db\backends\utils.py", line 85, in _execute
    return self.cursor.execute(sql, params)
  File "F:\virtual\demo\lib\site-packages\django\db\backends\mysql\base.py", line 71, in execute
    return self.cursor.execute(query, args)
  File "F:\virtual\demo\lib\site-packages\MySQLdb\cursors.py", line 206, in execute
    res = self._query(query)
  File "F:\virtual\demo\lib\site-packages\MySQLdb\cursors.py", line 319, in _query
    db.query(q)
  File "F:\virtual\demo\lib\site-packages\MySQLdb\connections.py", line 259, in query
    _mysql.connection.query(self, query)
MySQLdb._exceptions.OperationalError: (1054, "Unknown column 'nav.id' in 'field list'")

The above exception was the direct cause of the following exception:

Traceback (most recent call last):
  File "F:\virtual\demo\lib\site-packages\rest_framework\views.py", line 494, in dispatch
    response = handler(request, *args, **kwargs)
  File "F:\virtual\demo\lib\site-packages\rest_framework\generics.py", line 199, in get
    return self.list(request, *args, **kwargs)
  File "F:\virtual\demo\lib\site-packages\rest_framework\mixins.py", line 46, in list
    return Response(serializer.data)
  File "F:\virtual\demo\lib\site-packages\rest_framework\serializers.py", line 757, in data
    ret = super().data
  File "F:\virtual\demo\lib\site-packages\rest_framework\serializers.py", line 261, in data
    self._data = self.to_representation(self.instance)
  File "F:\virtual\demo\lib\site-packages\rest_framework\serializers.py", line 675, in to_representation
    self.child.to_representation(item) for item in iterable
  File "F:\virtual\demo\lib\site-packages\django\db\models\query.py", line 272, in __iter__
    self._fetch_all()
  File "F:\virtual\demo\lib\site-packages\django\db\models\query.py", line 1179, in _fetch_all
    self._result_cache = list(self._iterable_class(self))
  File "F:\virtual\demo\lib\site-packages\django\db\models\query.py", line 53, in __iter__
    results = compiler.execute_sql(chunked_fetch=self.chunked_fetch, chunk_size=self.chunk_size)
  File "F:\virtual\demo\lib\site-packages\django\db\models\sql\compiler.py", line 1068, in execute_sql
    cursor.execute(sql, params)
  File "F:\virtual\demo\lib\site-packages\django\db\backends\utils.py", line 100, in execute
    return super().execute(sql, params)
  File "F:\virtual\demo\lib\site-packages\django\db\backends\utils.py", line 68, in execute
    return self._execute_with_wrappers(sql, params, many=False, executor=self._execute)
  File "F:\virtual\demo\lib\site-packages\django\db\backends\utils.py", line 77, in _execute_with_wrappers
    return executor(sql, params, many, context)
  File "F:\virtual\demo\lib\site-packages\django\db\backends\utils.py", line 85, in _execute
    return self.cursor.execute(sql, params)
  File "F:\virtual\demo\lib\site-packages\django\db\utils.py", line 89, in __exit__
    raise dj_exc_value.with_traceback(traceback) from exc_value
  File "F:\virtual\demo\lib\site-packages\django\db\backends\utils.py", line 85, in _execute
    return self.cursor.execute(sql, params)
  File "F:\virtual\demo\lib\site-packages\django\db\backends\mysql\base.py", line 71, in execute
    return self.cursor.execute(query, args)
  File "F:\virtual\demo\lib\site-packages\MySQLdb\cursors.py", line 206, in execute
    res = self._query(query)
  File "F:\virtual\demo\lib\site-packages\MySQLdb\cursors.py", line 319, in _query
    db.query(q)
  File "F:\virtual\demo\lib\site-packages\MySQLdb\connections.py", line 259, in query
    _mysql.connection.query(self, query)
django.db.utils.OperationalError: (1054, "Unknown column 'nav.id' in 'field list'")

During handling of the above exception, another exception occurred:

Traceback (most recent call last):
  File "F:\virtual\demo\lib\site-packages\rest_framework\settings.py", line 177, in import_from_string
    return import_string(val)
  File "F:\virtual\demo\lib\site-packages\django\utils\module_loading.py", line 17, in import_string
    module = import_module(module_path)
  File "c:\python36\lib\importlib\__init__.py", line 126, in import_module
    return _bootstrap._gcd_import(name[level:], package, level)
  File "<frozen importlib._bootstrap>", line 994, in _gcd_import
  File "<frozen importlib._bootstrap>", line 971, in _find_and_load
  File "<frozen importlib._bootstrap>", line 941, in _find_and_load_unlocked
  File "<frozen importlib._bootstrap>", line 219, in _call_with_frames_removed
  File "<frozen importlib._bootstrap>", line 994, in _gcd_import
  File "<frozen importlib._bootstrap>", line 971, in _find_and_load
  File "<frozen importlib._bootstrap>", line 953, in _find_and_load_unlocked
ModuleNotFoundError: No module named 'drf_day4'

During handling of the above exception, another exception occurred:

Traceback (most recent call last):
  File "F:\virtual\demo\lib\site-packages\django\core\handlers\exception.py", line 35, in inner
    response = get_response(request)
  File "F:\virtual\demo\lib\site-packages\django\core\handlers\base.py", line 128, in _get_response
    response = self.process_exception_by_middleware(e, request)
  File "F:\virtual\demo\lib\site-packages\django\core\handlers\base.py", line 126, in _get_response
    response = wrapped_callback(request, *callback_args, **callback_kwargs)
  File "F:\virtual\demo\lib\site-packages\django\views\decorators\csrf.py", line 54, in wrapped_view
    return view_func(*args, **kwargs)
  File "F:\virtual\demo\lib\site-packages\django\views\generic\base.py", line 69, in view
    return self.dispatch(request, *args, **kwargs)
  File "F:\virtual\demo\lib\site-packages\rest_framework\views.py", line 497, in dispatch
    response = self.handle_exception(exc)
  File "F:\virtual\demo\lib\site-packages\rest_framework\views.py", line 451, in handle_exception
    exception_handler = self.get_exception_handler()
  File "F:\virtual\demo\lib\site-packages\rest_framework\views.py", line 298, in get_exception_handler
    return self.settings.EXCEPTION_HANDLER
  File "F:\virtual\demo\lib\site-packages\rest_framework\settings.py", line 220, in __getattr__
    val = perform_import(val, attr)
  File "F:\virtual\demo\lib\site-packages\rest_framework\settings.py", line 166, in perform_import
    return import_from_string(val, setting_name)
  File "F:\virtual\demo\lib\site-packages\rest_framework\settings.py", line 180, in import_from_string
    raise ImportError(msg)
ImportError: Could not import 'drf_day4.exceptions.exception_handler' for API setting 'EXCEPTION_HANDLER'. ModuleNotFoundError: No module named 'drf_day4'.
ERROR 2020-11-05 10:30:54,378 basehttp 124 "GET /home/footer/ HTTP/1.1" 500 233868
ERROR 2020-11-05 10:30:54,378 basehttp 124 "GET /home/banner/ HTTP/1.1" 500 233726
ERROR 2020-11-05 10:30:54,441 basehttp 124 "GET /home/header/ HTTP/1.1" 500 233877
ERROR 2020-11-05 10:31:19,518 exception 118 Internal Server Error: /home/header/
Traceback (most recent call last):
  File "F:\virtual\demo\lib\site-packages\django\db\backends\utils.py", line 85, in _execute
    return self.cursor.execute(sql, params)
  File "F:\virtual\demo\lib\site-packages\django\db\backends\mysql\base.py", line 71, in execute
    return self.cursor.execute(query, args)
  File "F:\virtual\demo\lib\site-packages\MySQLdb\cursors.py", line 206, in execute
    res = self._query(query)
  File "F:\virtual\demo\lib\site-packages\MySQLdb\cursors.py", line 319, in _query
    db.query(q)
  File "F:\virtual\demo\lib\site-packages\MySQLdb\connections.py", line 259, in query
    _mysql.connection.query(self, query)
MySQLdb._exceptions.OperationalError: (1054, "Unknown column 'nav.id' in 'field list'")

The above exception was the direct cause of the following exception:

Traceback (most recent call last):
  File "F:\virtual\demo\lib\site-packages\rest_framework\views.py", line 494, in dispatch
    response = handler(request, *args, **kwargs)
  File "F:\virtual\demo\lib\site-packages\rest_framework\generics.py", line 199, in get
    return self.list(request, *args, **kwargs)
  File "F:\virtual\demo\lib\site-packages\rest_framework\mixins.py", line 46, in list
    return Response(serializer.data)
  File "F:\virtual\demo\lib\site-packages\rest_framework\serializers.py", line 757, in data
    ret = super().data
  File "F:\virtual\demo\lib\site-packages\rest_framework\serializers.py", line 261, in data
    self._data = self.to_representation(self.instance)
  File "F:\virtual\demo\lib\site-packages\rest_framework\serializers.py", line 675, in to_representation
    self.child.to_representation(item) for item in iterable
  File "F:\virtual\demo\lib\site-packages\django\db\models\query.py", line 272, in __iter__
    self._fetch_all()
  File "F:\virtual\demo\lib\site-packages\django\db\models\query.py", line 1179, in _fetch_all
    self._result_cache = list(self._iterable_class(self))
  File "F:\virtual\demo\lib\site-packages\django\db\models\query.py", line 53, in __iter__
    results = compiler.execute_sql(chunked_fetch=self.chunked_fetch, chunk_size=self.chunk_size)
  File "F:\virtual\demo\lib\site-packages\django\db\models\sql\compiler.py", line 1068, in execute_sql
    cursor.execute(sql, params)
  File "F:\virtual\demo\lib\site-packages\django\db\backends\utils.py", line 100, in execute
    return super().execute(sql, params)
  File "F:\virtual\demo\lib\site-packages\django\db\backends\utils.py", line 68, in execute
    return self._execute_with_wrappers(sql, params, many=False, executor=self._execute)
  File "F:\virtual\demo\lib\site-packages\django\db\backends\utils.py", line 77, in _execute_with_wrappers
    return executor(sql, params, many, context)
  File "F:\virtual\demo\lib\site-packages\django\db\backends\utils.py", line 85, in _execute
    return self.cursor.execute(sql, params)
  File "F:\virtual\demo\lib\site-packages\django\db\utils.py", line 89, in __exit__
    raise dj_exc_value.with_traceback(traceback) from exc_value
  File "F:\virtual\demo\lib\site-packages\django\db\backends\utils.py", line 85, in _execute
    return self.cursor.execute(sql, params)
  File "F:\virtual\demo\lib\site-packages\django\db\backends\mysql\base.py", line 71, in execute
    return self.cursor.execute(query, args)
  File "F:\virtual\demo\lib\site-packages\MySQLdb\cursors.py", line 206, in execute
    res = self._query(query)
  File "F:\virtual\demo\lib\site-packages\MySQLdb\cursors.py", line 319, in _query
    db.query(q)
  File "F:\virtual\demo\lib\site-packages\MySQLdb\connections.py", line 259, in query
    _mysql.connection.query(self, query)
django.db.utils.OperationalError: (1054, "Unknown column 'nav.id' in 'field list'")

During handling of the above exception, another exception occurred:

Traceback (most recent call last):
  File "F:\virtual\demo\lib\site-packages\rest_framework\settings.py", line 177, in import_from_string
    return import_string(val)
  File "F:\virtual\demo\lib\site-packages\django\utils\module_loading.py", line 17, in import_string
    module = import_module(module_path)
  File "c:\python36\lib\importlib\__init__.py", line 126, in import_module
    return _bootstrap._gcd_import(name[level:], package, level)
  File "<frozen importlib._bootstrap>", line 994, in _gcd_import
  File "<frozen importlib._bootstrap>", line 971, in _find_and_load
  File "<frozen importlib._bootstrap>", line 941, in _find_and_load_unlocked
  File "<frozen importlib._bootstrap>", line 219, in _call_with_frames_removed
  File "<frozen importlib._bootstrap>", line 994, in _gcd_import
  File "<frozen importlib._bootstrap>", line 971, in _find_and_load
  File "<frozen importlib._bootstrap>", line 953, in _find_and_load_unlocked
ModuleNotFoundError: No module named 'drf_day4'

During handling of the above exception, another exception occurred:

Traceback (most recent call last):
  File "F:\virtual\demo\lib\site-packages\django\core\handlers\exception.py", line 35, in inner
    response = get_response(request)
  File "F:\virtual\demo\lib\site-packages\django\core\handlers\base.py", line 128, in _get_response
    response = self.process_exception_by_middleware(e, request)
  File "F:\virtual\demo\lib\site-packages\django\core\handlers\base.py", line 126, in _get_response
    response = wrapped_callback(request, *callback_args, **callback_kwargs)
  File "F:\virtual\demo\lib\site-packages\django\views\decorators\csrf.py", line 54, in wrapped_view
    return view_func(*args, **kwargs)
  File "F:\virtual\demo\lib\site-packages\django\views\generic\base.py", line 69, in view
    return self.dispatch(request, *args, **kwargs)
  File "F:\virtual\demo\lib\site-packages\rest_framework\views.py", line 497, in dispatch
    response = self.handle_exception(exc)
  File "F:\virtual\demo\lib\site-packages\rest_framework\views.py", line 451, in handle_exception
    exception_handler = self.get_exception_handler()
  File "F:\virtual\demo\lib\site-packages\rest_framework\views.py", line 298, in get_exception_handler
    return self.settings.EXCEPTION_HANDLER
  File "F:\virtual\demo\lib\site-packages\rest_framework\settings.py", line 220, in __getattr__
    val = perform_import(val, attr)
  File "F:\virtual\demo\lib\site-packages\rest_framework\settings.py", line 166, in perform_import
    return import_from_string(val, setting_name)
  File "F:\virtual\demo\lib\site-packages\rest_framework\settings.py", line 180, in import_from_string
    raise ImportError(msg)
ImportError: Could not import 'drf_day4.exceptions.exception_handler' for API setting 'EXCEPTION_HANDLER'. ModuleNotFoundError: No module named 'drf_day4'.
ERROR 2020-11-05 10:31:19,520 exception 118 Internal Server Error: /home/banner/
Traceback (most recent call last):
  File "F:\virtual\demo\lib\site-packages\django\db\backends\utils.py", line 85, in _execute
    return self.cursor.execute(sql, params)
  File "F:\virtual\demo\lib\site-packages\django\db\backends\mysql\base.py", line 71, in execute
    return self.cursor.execute(query, args)
  File "F:\virtual\demo\lib\site-packages\MySQLdb\cursors.py", line 206, in execute
    res = self._query(query)
  File "F:\virtual\demo\lib\site-packages\MySQLdb\cursors.py", line 319, in _query
    db.query(q)
  File "F:\virtual\demo\lib\site-packages\MySQLdb\connections.py", line 259, in query
    _mysql.connection.query(self, query)
MySQLdb._exceptions.OperationalError: (1054, "Unknown column 'banner.id' in 'field list'")

The above exception was the direct cause of the following exception:

Traceback (most recent call last):
  File "F:\virtual\demo\lib\site-packages\rest_framework\views.py", line 494, in dispatch
    response = handler(request, *args, **kwargs)
  File "F:\virtual\demo\lib\site-packages\rest_framework\generics.py", line 199, in get
    return self.list(request, *args, **kwargs)
  File "F:\virtual\demo\lib\site-packages\rest_framework\mixins.py", line 46, in list
    return Response(serializer.data)
  File "F:\virtual\demo\lib\site-packages\rest_framework\serializers.py", line 757, in data
    ret = super().data
  File "F:\virtual\demo\lib\site-packages\rest_framework\serializers.py", line 261, in data
    self._data = self.to_representation(self.instance)
  File "F:\virtual\demo\lib\site-packages\rest_framework\serializers.py", line 675, in to_representation
    self.child.to_representation(item) for item in iterable
  File "F:\virtual\demo\lib\site-packages\django\db\models\query.py", line 272, in __iter__
    self._fetch_all()
  File "F:\virtual\demo\lib\site-packages\django\db\models\query.py", line 1179, in _fetch_all
    self._result_cache = list(self._iterable_class(self))
  File "F:\virtual\demo\lib\site-packages\django\db\models\query.py", line 53, in __iter__
    results = compiler.execute_sql(chunked_fetch=self.chunked_fetch, chunk_size=self.chunk_size)
  File "F:\virtual\demo\lib\site-packages\django\db\models\sql\compiler.py", line 1068, in execute_sql
    cursor.execute(sql, params)
  File "F:\virtual\demo\lib\site-packages\django\db\backends\utils.py", line 100, in execute
    return super().execute(sql, params)
  File "F:\virtual\demo\lib\site-packages\django\db\backends\utils.py", line 68, in execute
    return self._execute_with_wrappers(sql, params, many=False, executor=self._execute)
  File "F:\virtual\demo\lib\site-packages\django\db\backends\utils.py", line 77, in _execute_with_wrappers
    return executor(sql, params, many, context)
  File "F:\virtual\demo\lib\site-packages\django\db\backends\utils.py", line 85, in _execute
    return self.cursor.execute(sql, params)
  File "F:\virtual\demo\lib\site-packages\django\db\utils.py", line 89, in __exit__
    raise dj_exc_value.with_traceback(traceback) from exc_value
  File "F:\virtual\demo\lib\site-packages\django\db\backends\utils.py", line 85, in _execute
    return self.cursor.execute(sql, params)
  File "F:\virtual\demo\lib\site-packages\django\db\backends\mysql\base.py", line 71, in execute
    return self.cursor.execute(query, args)
  File "F:\virtual\demo\lib\site-packages\MySQLdb\cursors.py", line 206, in execute
    res = self._query(query)
  File "F:\virtual\demo\lib\site-packages\MySQLdb\cursors.py", line 319, in _query
    db.query(q)
  File "F:\virtual\demo\lib\site-packages\MySQLdb\connections.py", line 259, in query
    _mysql.connection.query(self, query)
django.db.utils.OperationalError: (1054, "Unknown column 'banner.id' in 'field list'")

During handling of the above exception, another exception occurred:

Traceback (most recent call last):
  File "F:\virtual\demo\lib\site-packages\rest_framework\settings.py", line 177, in import_from_string
    return import_string(val)
  File "F:\virtual\demo\lib\site-packages\django\utils\module_loading.py", line 17, in import_string
    module = import_module(module_path)
  File "c:\python36\lib\importlib\__init__.py", line 126, in import_module
    return _bootstrap._gcd_import(name[level:], package, level)
  File "<frozen importlib._bootstrap>", line 994, in _gcd_import
  File "<frozen importlib._bootstrap>", line 971, in _find_and_load
  File "<frozen importlib._bootstrap>", line 941, in _find_and_load_unlocked
  File "<frozen importlib._bootstrap>", line 219, in _call_with_frames_removed
  File "<frozen importlib._bootstrap>", line 994, in _gcd_import
  File "<frozen importlib._bootstrap>", line 971, in _find_and_load
  File "<frozen importlib._bootstrap>", line 953, in _find_and_load_unlocked
ModuleNotFoundError: No module named 'drf_day4'

During handling of the above exception, another exception occurred:

Traceback (most recent call last):
  File "F:\virtual\demo\lib\site-packages\django\core\handlers\exception.py", line 35, in inner
    response = get_response(request)
  File "F:\virtual\demo\lib\site-packages\django\core\handlers\base.py", line 128, in _get_response
    response = self.process_exception_by_middleware(e, request)
  File "F:\virtual\demo\lib\site-packages\django\core\handlers\base.py", line 126, in _get_response
    response = wrapped_callback(request, *callback_args, **callback_kwargs)
  File "F:\virtual\demo\lib\site-packages\django\views\decorators\csrf.py", line 54, in wrapped_view
    return view_func(*args, **kwargs)
  File "F:\virtual\demo\lib\site-packages\django\views\generic\base.py", line 69, in view
    return self.dispatch(request, *args, **kwargs)
  File "F:\virtual\demo\lib\site-packages\rest_framework\views.py", line 497, in dispatch
    response = self.handle_exception(exc)
  File "F:\virtual\demo\lib\site-packages\rest_framework\views.py", line 451, in handle_exception
    exception_handler = self.get_exception_handler()
  File "F:\virtual\demo\lib\site-packages\rest_framework\views.py", line 298, in get_exception_handler
    return self.settings.EXCEPTION_HANDLER
  File "F:\virtual\demo\lib\site-packages\rest_framework\settings.py", line 220, in __getattr__
    val = perform_import(val, attr)
  File "F:\virtual\demo\lib\site-packages\rest_framework\settings.py", line 166, in perform_import
    return import_from_string(val, setting_name)
  File "F:\virtual\demo\lib\site-packages\rest_framework\settings.py", line 180, in import_from_string
    raise ImportError(msg)
ImportError: Could not import 'drf_day4.exceptions.exception_handler' for API setting 'EXCEPTION_HANDLER'. ModuleNotFoundError: No module named 'drf_day4'.
ERROR 2020-11-05 10:31:19,521 exception 118 Internal Server Error: /home/footer/
Traceback (most recent call last):
  File "F:\virtual\demo\lib\site-packages\django\db\backends\utils.py", line 85, in _execute
    return self.cursor.execute(sql, params)
  File "F:\virtual\demo\lib\site-packages\django\db\backends\mysql\base.py", line 71, in execute
    return self.cursor.execute(query, args)
  File "F:\virtual\demo\lib\site-packages\MySQLdb\cursors.py", line 206, in execute
    res = self._query(query)
  File "F:\virtual\demo\lib\site-packages\MySQLdb\cursors.py", line 319, in _query
    db.query(q)
  File "F:\virtual\demo\lib\site-packages\MySQLdb\connections.py", line 259, in query
    _mysql.connection.query(self, query)
MySQLdb._exceptions.OperationalError: (1054, "Unknown column 'nav.id' in 'field list'")

The above exception was the direct cause of the following exception:

Traceback (most recent call last):
  File "F:\virtual\demo\lib\site-packages\rest_framework\views.py", line 494, in dispatch
    response = handler(request, *args, **kwargs)
  File "F:\virtual\demo\lib\site-packages\rest_framework\generics.py", line 199, in get
    return self.list(request, *args, **kwargs)
  File "F:\virtual\demo\lib\site-packages\rest_framework\mixins.py", line 46, in list
    return Response(serializer.data)
  File "F:\virtual\demo\lib\site-packages\rest_framework\serializers.py", line 757, in data
    ret = super().data
  File "F:\virtual\demo\lib\site-packages\rest_framework\serializers.py", line 261, in data
    self._data = self.to_representation(self.instance)
  File "F:\virtual\demo\lib\site-packages\rest_framework\serializers.py", line 675, in to_representation
    self.child.to_representation(item) for item in iterable
  File "F:\virtual\demo\lib\site-packages\django\db\models\query.py", line 272, in __iter__
    self._fetch_all()
  File "F:\virtual\demo\lib\site-packages\django\db\models\query.py", line 1179, in _fetch_all
    self._result_cache = list(self._iterable_class(self))
  File "F:\virtual\demo\lib\site-packages\django\db\models\query.py", line 53, in __iter__
    results = compiler.execute_sql(chunked_fetch=self.chunked_fetch, chunk_size=self.chunk_size)
  File "F:\virtual\demo\lib\site-packages\django\db\models\sql\compiler.py", line 1068, in execute_sql
    cursor.execute(sql, params)
  File "F:\virtual\demo\lib\site-packages\django\db\backends\utils.py", line 100, in execute
    return super().execute(sql, params)
  File "F:\virtual\demo\lib\site-packages\django\db\backends\utils.py", line 68, in execute
    return self._execute_with_wrappers(sql, params, many=False, executor=self._execute)
  File "F:\virtual\demo\lib\site-packages\django\db\backends\utils.py", line 77, in _execute_with_wrappers
    return executor(sql, params, many, context)
  File "F:\virtual\demo\lib\site-packages\django\db\backends\utils.py", line 85, in _execute
    return self.cursor.execute(sql, params)
  File "F:\virtual\demo\lib\site-packages\django\db\utils.py", line 89, in __exit__
    raise dj_exc_value.with_traceback(traceback) from exc_value
  File "F:\virtual\demo\lib\site-packages\django\db\backends\utils.py", line 85, in _execute
    return self.cursor.execute(sql, params)
  File "F:\virtual\demo\lib\site-packages\django\db\backends\mysql\base.py", line 71, in execute
    return self.cursor.execute(query, args)
  File "F:\virtual\demo\lib\site-packages\MySQLdb\cursors.py", line 206, in execute
    res = self._query(query)
  File "F:\virtual\demo\lib\site-packages\MySQLdb\cursors.py", line 319, in _query
    db.query(q)
  File "F:\virtual\demo\lib\site-packages\MySQLdb\connections.py", line 259, in query
    _mysql.connection.query(self, query)
django.db.utils.OperationalError: (1054, "Unknown column 'nav.id' in 'field list'")

During handling of the above exception, another exception occurred:

Traceback (most recent call last):
  File "F:\virtual\demo\lib\site-packages\rest_framework\settings.py", line 177, in import_from_string
    return import_string(val)
  File "F:\virtual\demo\lib\site-packages\django\utils\module_loading.py", line 17, in import_string
    module = import_module(module_path)
  File "c:\python36\lib\importlib\__init__.py", line 126, in import_module
    return _bootstrap._gcd_import(name[level:], package, level)
  File "<frozen importlib._bootstrap>", line 994, in _gcd_import
  File "<frozen importlib._bootstrap>", line 971, in _find_and_load
  File "<frozen importlib._bootstrap>", line 941, in _find_and_load_unlocked
  File "<frozen importlib._bootstrap>", line 219, in _call_with_frames_removed
  File "<frozen importlib._bootstrap>", line 994, in _gcd_import
  File "<frozen importlib._bootstrap>", line 971, in _find_and_load
  File "<frozen importlib._bootstrap>", line 953, in _find_and_load_unlocked
ModuleNotFoundError: No module named 'drf_day4'

During handling of the above exception, another exception occurred:

Traceback (most recent call last):
  File "F:\virtual\demo\lib\site-packages\django\core\handlers\exception.py", line 35, in inner
    response = get_response(request)
  File "F:\virtual\demo\lib\site-packages\django\core\handlers\base.py", line 128, in _get_response
    response = self.process_exception_by_middleware(e, request)
  File "F:\virtual\demo\lib\site-packages\django\core\handlers\base.py", line 126, in _get_response
    response = wrapped_callback(request, *callback_args, **callback_kwargs)
  File "F:\virtual\demo\lib\site-packages\django\views\decorators\csrf.py", line 54, in wrapped_view
    return view_func(*args, **kwargs)
  File "F:\virtual\demo\lib\site-packages\django\views\generic\base.py", line 69, in view
    return self.dispatch(request, *args, **kwargs)
  File "F:\virtual\demo\lib\site-packages\rest_framework\views.py", line 497, in dispatch
    response = self.handle_exception(exc)
  File "F:\virtual\demo\lib\site-packages\rest_framework\views.py", line 451, in handle_exception
    exception_handler = self.get_exception_handler()
  File "F:\virtual\demo\lib\site-packages\rest_framework\views.py", line 298, in get_exception_handler
    return self.settings.EXCEPTION_HANDLER
  File "F:\virtual\demo\lib\site-packages\rest_framework\settings.py", line 220, in __getattr__
    val = perform_import(val, attr)
  File "F:\virtual\demo\lib\site-packages\rest_framework\settings.py", line 166, in perform_import
    return import_from_string(val, setting_name)
  File "F:\virtual\demo\lib\site-packages\rest_framework\settings.py", line 180, in import_from_string
    raise ImportError(msg)
ImportError: Could not import 'drf_day4.exceptions.exception_handler' for API setting 'EXCEPTION_HANDLER'. ModuleNotFoundError: No module named 'drf_day4'.
ERROR 2020-11-05 10:31:19,708 basehttp 124 "GET /home/header/ HTTP/1.1" 500 233857
ERROR 2020-11-05 10:31:19,708 basehttp 124 "GET /home/banner/ HTTP/1.1" 500 233706
ERROR 2020-11-05 10:31:19,777 basehttp 124 "GET /home/footer/ HTTP/1.1" 500 233868
ERROR 2020-11-05 10:34:02,359 exception 118 Internal Server Error: /home/banner/
Traceback (most recent call last):
  File "F:\virtual\demo\lib\site-packages\django\db\backends\utils.py", line 85, in _execute
    return self.cursor.execute(sql, params)
  File "F:\virtual\demo\lib\site-packages\django\db\backends\mysql\base.py", line 71, in execute
    return self.cursor.execute(query, args)
  File "F:\virtual\demo\lib\site-packages\MySQLdb\cursors.py", line 206, in execute
    res = self._query(query)
  File "F:\virtual\demo\lib\site-packages\MySQLdb\cursors.py", line 319, in _query
    db.query(q)
  File "F:\virtual\demo\lib\site-packages\MySQLdb\connections.py", line 259, in query
    _mysql.connection.query(self, query)
MySQLdb._exceptions.OperationalError: (1054, "Unknown column 'banner.id' in 'field list'")

The above exception was the direct cause of the following exception:

Traceback (most recent call last):
  File "F:\virtual\demo\lib\site-packages\rest_framework\views.py", line 494, in dispatch
    response = handler(request, *args, **kwargs)
  File "F:\virtual\demo\lib\site-packages\rest_framework\generics.py", line 199, in get
    return self.list(request, *args, **kwargs)
  File "F:\virtual\demo\lib\site-packages\rest_framework\mixins.py", line 46, in list
    return Response(serializer.data)
  File "F:\virtual\demo\lib\site-packages\rest_framework\serializers.py", line 757, in data
    ret = super().data
  File "F:\virtual\demo\lib\site-packages\rest_framework\serializers.py", line 261, in data
    self._data = self.to_representation(self.instance)
  File "F:\virtual\demo\lib\site-packages\rest_framework\serializers.py", line 675, in to_representation
    self.child.to_representation(item) for item in iterable
  File "F:\virtual\demo\lib\site-packages\django\db\models\query.py", line 272, in __iter__
    self._fetch_all()
  File "F:\virtual\demo\lib\site-packages\django\db\models\query.py", line 1179, in _fetch_all
    self._result_cache = list(self._iterable_class(self))
  File "F:\virtual\demo\lib\site-packages\django\db\models\query.py", line 53, in __iter__
    results = compiler.execute_sql(chunked_fetch=self.chunked_fetch, chunk_size=self.chunk_size)
  File "F:\virtual\demo\lib\site-packages\django\db\models\sql\compiler.py", line 1068, in execute_sql
    cursor.execute(sql, params)
  File "F:\virtual\demo\lib\site-packages\django\db\backends\utils.py", line 100, in execute
    return super().execute(sql, params)
  File "F:\virtual\demo\lib\site-packages\django\db\backends\utils.py", line 68, in execute
    return self._execute_with_wrappers(sql, params, many=False, executor=self._execute)
  File "F:\virtual\demo\lib\site-packages\django\db\backends\utils.py", line 77, in _execute_with_wrappers
    return executor(sql, params, many, context)
  File "F:\virtual\demo\lib\site-packages\django\db\backends\utils.py", line 85, in _execute
    return self.cursor.execute(sql, params)
  File "F:\virtual\demo\lib\site-packages\django\db\utils.py", line 89, in __exit__
    raise dj_exc_value.with_traceback(traceback) from exc_value
  File "F:\virtual\demo\lib\site-packages\django\db\backends\utils.py", line 85, in _execute
    return self.cursor.execute(sql, params)
  File "F:\virtual\demo\lib\site-packages\django\db\backends\mysql\base.py", line 71, in execute
    return self.cursor.execute(query, args)
  File "F:\virtual\demo\lib\site-packages\MySQLdb\cursors.py", line 206, in execute
    res = self._query(query)
  File "F:\virtual\demo\lib\site-packages\MySQLdb\cursors.py", line 319, in _query
    db.query(q)
  File "F:\virtual\demo\lib\site-packages\MySQLdb\connections.py", line 259, in query
    _mysql.connection.query(self, query)
django.db.utils.OperationalError: (1054, "Unknown column 'banner.id' in 'field list'")

During handling of the above exception, another exception occurred:

Traceback (most recent call last):
  File "F:\virtual\demo\lib\site-packages\rest_framework\settings.py", line 177, in import_from_string
    return import_string(val)
  File "F:\virtual\demo\lib\site-packages\django\utils\module_loading.py", line 17, in import_string
    module = import_module(module_path)
  File "c:\python36\lib\importlib\__init__.py", line 126, in import_module
    return _bootstrap._gcd_import(name[level:], package, level)
  File "<frozen importlib._bootstrap>", line 994, in _gcd_import
  File "<frozen importlib._bootstrap>", line 971, in _find_and_load
  File "<frozen importlib._bootstrap>", line 941, in _find_and_load_unlocked
  File "<frozen importlib._bootstrap>", line 219, in _call_with_frames_removed
  File "<frozen importlib._bootstrap>", line 994, in _gcd_import
  File "<frozen importlib._bootstrap>", line 971, in _find_and_load
  File "<frozen importlib._bootstrap>", line 953, in _find_and_load_unlocked
ModuleNotFoundError: No module named 'drf_day4'

During handling of the above exception, another exception occurred:

Traceback (most recent call last):
  File "F:\virtual\demo\lib\site-packages\django\core\handlers\exception.py", line 35, in inner
    response = get_response(request)
  File "F:\virtual\demo\lib\site-packages\django\core\handlers\base.py", line 128, in _get_response
    response = self.process_exception_by_middleware(e, request)
  File "F:\virtual\demo\lib\site-packages\django\core\handlers\base.py", line 126, in _get_response
    response = wrapped_callback(request, *callback_args, **callback_kwargs)
  File "F:\virtual\demo\lib\site-packages\django\views\decorators\csrf.py", line 54, in wrapped_view
    return view_func(*args, **kwargs)
  File "F:\virtual\demo\lib\site-packages\django\views\generic\base.py", line 69, in view
    return self.dispatch(request, *args, **kwargs)
  File "F:\virtual\demo\lib\site-packages\rest_framework\views.py", line 497, in dispatch
    response = self.handle_exception(exc)
  File "F:\virtual\demo\lib\site-packages\rest_framework\views.py", line 451, in handle_exception
    exception_handler = self.get_exception_handler()
  File "F:\virtual\demo\lib\site-packages\rest_framework\views.py", line 298, in get_exception_handler
    return self.settings.EXCEPTION_HANDLER
  File "F:\virtual\demo\lib\site-packages\rest_framework\settings.py", line 220, in __getattr__
    val = perform_import(val, attr)
  File "F:\virtual\demo\lib\site-packages\rest_framework\settings.py", line 166, in perform_import
    return import_from_string(val, setting_name)
  File "F:\virtual\demo\lib\site-packages\rest_framework\settings.py", line 180, in import_from_string
    raise ImportError(msg)
ImportError: Could not import 'drf_day4.exceptions.exception_handler' for API setting 'EXCEPTION_HANDLER'. ModuleNotFoundError: No module named 'drf_day4'.
ERROR 2020-11-05 10:34:02,361 exception 118 Internal Server Error: /home/header/
Traceback (most recent call last):
  File "F:\virtual\demo\lib\site-packages\django\db\backends\utils.py", line 85, in _execute
    return self.cursor.execute(sql, params)
  File "F:\virtual\demo\lib\site-packages\django\db\backends\mysql\base.py", line 71, in execute
    return self.cursor.execute(query, args)
  File "F:\virtual\demo\lib\site-packages\MySQLdb\cursors.py", line 206, in execute
    res = self._query(query)
  File "F:\virtual\demo\lib\site-packages\MySQLdb\cursors.py", line 319, in _query
    db.query(q)
  File "F:\virtual\demo\lib\site-packages\MySQLdb\connections.py", line 259, in query
    _mysql.connection.query(self, query)
MySQLdb._exceptions.OperationalError: (1054, "Unknown column 'nav.id' in 'field list'")

The above exception was the direct cause of the following exception:

Traceback (most recent call last):
  File "F:\virtual\demo\lib\site-packages\rest_framework\views.py", line 494, in dispatch
    response = handler(request, *args, **kwargs)
  File "F:\virtual\demo\lib\site-packages\rest_framework\generics.py", line 199, in get
    return self.list(request, *args, **kwargs)
  File "F:\virtual\demo\lib\site-packages\rest_framework\mixins.py", line 46, in list
    return Response(serializer.data)
  File "F:\virtual\demo\lib\site-packages\rest_framework\serializers.py", line 757, in data
    ret = super().data
  File "F:\virtual\demo\lib\site-packages\rest_framework\serializers.py", line 261, in data
    self._data = self.to_representation(self.instance)
  File "F:\virtual\demo\lib\site-packages\rest_framework\serializers.py", line 675, in to_representation
    self.child.to_representation(item) for item in iterable
  File "F:\virtual\demo\lib\site-packages\django\db\models\query.py", line 272, in __iter__
    self._fetch_all()
  File "F:\virtual\demo\lib\site-packages\django\db\models\query.py", line 1179, in _fetch_all
    self._result_cache = list(self._iterable_class(self))
  File "F:\virtual\demo\lib\site-packages\django\db\models\query.py", line 53, in __iter__
    results = compiler.execute_sql(chunked_fetch=self.chunked_fetch, chunk_size=self.chunk_size)
  File "F:\virtual\demo\lib\site-packages\django\db\models\sql\compiler.py", line 1068, in execute_sql
    cursor.execute(sql, params)
  File "F:\virtual\demo\lib\site-packages\django\db\backends\utils.py", line 100, in execute
    return super().execute(sql, params)
  File "F:\virtual\demo\lib\site-packages\django\db\backends\utils.py", line 68, in execute
    return self._execute_with_wrappers(sql, params, many=False, executor=self._execute)
  File "F:\virtual\demo\lib\site-packages\django\db\backends\utils.py", line 77, in _execute_with_wrappers
    return executor(sql, params, many, context)
  File "F:\virtual\demo\lib\site-packages\django\db\backends\utils.py", line 85, in _execute
    return self.cursor.execute(sql, params)
  File "F:\virtual\demo\lib\site-packages\django\db\utils.py", line 89, in __exit__
    raise dj_exc_value.with_traceback(traceback) from exc_value
  File "F:\virtual\demo\lib\site-packages\django\db\backends\utils.py", line 85, in _execute
    return self.cursor.execute(sql, params)
  File "F:\virtual\demo\lib\site-packages\django\db\backends\mysql\base.py", line 71, in execute
    return self.cursor.execute(query, args)
  File "F:\virtual\demo\lib\site-packages\MySQLdb\cursors.py", line 206, in execute
    res = self._query(query)
  File "F:\virtual\demo\lib\site-packages\MySQLdb\cursors.py", line 319, in _query
    db.query(q)
  File "F:\virtual\demo\lib\site-packages\MySQLdb\connections.py", line 259, in query
    _mysql.connection.query(self, query)
django.db.utils.OperationalError: (1054, "Unknown column 'nav.id' in 'field list'")

During handling of the above exception, another exception occurred:

Traceback (most recent call last):
  File "F:\virtual\demo\lib\site-packages\rest_framework\settings.py", line 177, in import_from_string
    return import_string(val)
  File "F:\virtual\demo\lib\site-packages\django\utils\module_loading.py", line 17, in import_string
    module = import_module(module_path)
  File "c:\python36\lib\importlib\__init__.py", line 126, in import_module
    return _bootstrap._gcd_import(name[level:], package, level)
  File "<frozen importlib._bootstrap>", line 994, in _gcd_import
  File "<frozen importlib._bootstrap>", line 971, in _find_and_load
  File "<frozen importlib._bootstrap>", line 941, in _find_and_load_unlocked
  File "<frozen importlib._bootstrap>", line 219, in _call_with_frames_removed
  File "<frozen importlib._bootstrap>", line 994, in _gcd_import
  File "<frozen importlib._bootstrap>", line 971, in _find_and_load
  File "<frozen importlib._bootstrap>", line 953, in _find_and_load_unlocked
ModuleNotFoundError: No module named 'drf_day4'

During handling of the above exception, another exception occurred:

Traceback (most recent call last):
  File "F:\virtual\demo\lib\site-packages\django\core\handlers\exception.py", line 35, in inner
    response = get_response(request)
  File "F:\virtual\demo\lib\site-packages\django\core\handlers\base.py", line 128, in _get_response
    response = self.process_exception_by_middleware(e, request)
  File "F:\virtual\demo\lib\site-packages\django\core\handlers\base.py", line 126, in _get_response
    response = wrapped_callback(request, *callback_args, **callback_kwargs)
  File "F:\virtual\demo\lib\site-packages\django\views\decorators\csrf.py", line 54, in wrapped_view
    return view_func(*args, **kwargs)
  File "F:\virtual\demo\lib\site-packages\django\views\generic\base.py", line 69, in view
    return self.dispatch(request, *args, **kwargs)
  File "F:\virtual\demo\lib\site-packages\rest_framework\views.py", line 497, in dispatch
    response = self.handle_exception(exc)
  File "F:\virtual\demo\lib\site-packages\rest_framework\views.py", line 451, in handle_exception
    exception_handler = self.get_exception_handler()
  File "F:\virtual\demo\lib\site-packages\rest_framework\views.py", line 298, in get_exception_handler
    return self.settings.EXCEPTION_HANDLER
  File "F:\virtual\demo\lib\site-packages\rest_framework\settings.py", line 220, in __getattr__
    val = perform_import(val, attr)
  File "F:\virtual\demo\lib\site-packages\rest_framework\settings.py", line 166, in perform_import
    return import_from_string(val, setting_name)
  File "F:\virtual\demo\lib\site-packages\rest_framework\settings.py", line 180, in import_from_string
    raise ImportError(msg)
ImportError: Could not import 'drf_day4.exceptions.exception_handler' for API setting 'EXCEPTION_HANDLER'. ModuleNotFoundError: No module named 'drf_day4'.
ERROR 2020-11-05 10:34:02,363 exception 118 Internal Server Error: /home/footer/
Traceback (most recent call last):
  File "F:\virtual\demo\lib\site-packages\django\db\backends\utils.py", line 85, in _execute
    return self.cursor.execute(sql, params)
  File "F:\virtual\demo\lib\site-packages\django\db\backends\mysql\base.py", line 71, in execute
    return self.cursor.execute(query, args)
  File "F:\virtual\demo\lib\site-packages\MySQLdb\cursors.py", line 206, in execute
    res = self._query(query)
  File "F:\virtual\demo\lib\site-packages\MySQLdb\cursors.py", line 319, in _query
    db.query(q)
  File "F:\virtual\demo\lib\site-packages\MySQLdb\connections.py", line 259, in query
    _mysql.connection.query(self, query)
MySQLdb._exceptions.OperationalError: (1054, "Unknown column 'nav.id' in 'field list'")

The above exception was the direct cause of the following exception:

Traceback (most recent call last):
  File "F:\virtual\demo\lib\site-packages\rest_framework\views.py", line 494, in dispatch
    response = handler(request, *args, **kwargs)
  File "F:\virtual\demo\lib\site-packages\rest_framework\generics.py", line 199, in get
    return self.list(request, *args, **kwargs)
  File "F:\virtual\demo\lib\site-packages\rest_framework\mixins.py", line 46, in list
    return Response(serializer.data)
  File "F:\virtual\demo\lib\site-packages\rest_framework\serializers.py", line 757, in data
    ret = super().data
  File "F:\virtual\demo\lib\site-packages\rest_framework\serializers.py", line 261, in data
    self._data = self.to_representation(self.instance)
  File "F:\virtual\demo\lib\site-packages\rest_framework\serializers.py", line 675, in to_representation
    self.child.to_representation(item) for item in iterable
  File "F:\virtual\demo\lib\site-packages\django\db\models\query.py", line 272, in __iter__
    self._fetch_all()
  File "F:\virtual\demo\lib\site-packages\django\db\models\query.py", line 1179, in _fetch_all
    self._result_cache = list(self._iterable_class(self))
  File "F:\virtual\demo\lib\site-packages\django\db\models\query.py", line 53, in __iter__
    results = compiler.execute_sql(chunked_fetch=self.chunked_fetch, chunk_size=self.chunk_size)
  File "F:\virtual\demo\lib\site-packages\django\db\models\sql\compiler.py", line 1068, in execute_sql
    cursor.execute(sql, params)
  File "F:\virtual\demo\lib\site-packages\django\db\backends\utils.py", line 100, in execute
    return super().execute(sql, params)
  File "F:\virtual\demo\lib\site-packages\django\db\backends\utils.py", line 68, in execute
    return self._execute_with_wrappers(sql, params, many=False, executor=self._execute)
  File "F:\virtual\demo\lib\site-packages\django\db\backends\utils.py", line 77, in _execute_with_wrappers
    return executor(sql, params, many, context)
  File "F:\virtual\demo\lib\site-packages\django\db\backends\utils.py", line 85, in _execute
    return self.cursor.execute(sql, params)
  File "F:\virtual\demo\lib\site-packages\django\db\utils.py", line 89, in __exit__
    raise dj_exc_value.with_traceback(traceback) from exc_value
  File "F:\virtual\demo\lib\site-packages\django\db\backends\utils.py", line 85, in _execute
    return self.cursor.execute(sql, params)
  File "F:\virtual\demo\lib\site-packages\django\db\backends\mysql\base.py", line 71, in execute
    return self.cursor.execute(query, args)
  File "F:\virtual\demo\lib\site-packages\MySQLdb\cursors.py", line 206, in execute
    res = self._query(query)
  File "F:\virtual\demo\lib\site-packages\MySQLdb\cursors.py", line 319, in _query
    db.query(q)
  File "F:\virtual\demo\lib\site-packages\MySQLdb\connections.py", line 259, in query
    _mysql.connection.query(self, query)
django.db.utils.OperationalError: (1054, "Unknown column 'nav.id' in 'field list'")

During handling of the above exception, another exception occurred:

Traceback (most recent call last):
  File "F:\virtual\demo\lib\site-packages\rest_framework\settings.py", line 177, in import_from_string
    return import_string(val)
  File "F:\virtual\demo\lib\site-packages\django\utils\module_loading.py", line 17, in import_string
    module = import_module(module_path)
  File "c:\python36\lib\importlib\__init__.py", line 126, in import_module
    return _bootstrap._gcd_import(name[level:], package, level)
  File "<frozen importlib._bootstrap>", line 994, in _gcd_import
  File "<frozen importlib._bootstrap>", line 971, in _find_and_load
  File "<frozen importlib._bootstrap>", line 941, in _find_and_load_unlocked
  File "<frozen importlib._bootstrap>", line 219, in _call_with_frames_removed
  File "<frozen importlib._bootstrap>", line 994, in _gcd_import
  File "<frozen importlib._bootstrap>", line 971, in _find_and_load
  File "<frozen importlib._bootstrap>", line 953, in _find_and_load_unlocked
ModuleNotFoundError: No module named 'drf_day4'

During handling of the above exception, another exception occurred:

Traceback (most recent call last):
  File "F:\virtual\demo\lib\site-packages\django\core\handlers\exception.py", line 35, in inner
    response = get_response(request)
  File "F:\virtual\demo\lib\site-packages\django\core\handlers\base.py", line 128, in _get_response
    response = self.process_exception_by_middleware(e, request)
  File "F:\virtual\demo\lib\site-packages\django\core\handlers\base.py", line 126, in _get_response
    response = wrapped_callback(request, *callback_args, **callback_kwargs)
  File "F:\virtual\demo\lib\site-packages\django\views\decorators\csrf.py", line 54, in wrapped_view
    return view_func(*args, **kwargs)
  File "F:\virtual\demo\lib\site-packages\django\views\generic\base.py", line 69, in view
    return self.dispatch(request, *args, **kwargs)
  File "F:\virtual\demo\lib\site-packages\rest_framework\views.py", line 497, in dispatch
    response = self.handle_exception(exc)
  File "F:\virtual\demo\lib\site-packages\rest_framework\views.py", line 451, in handle_exception
    exception_handler = self.get_exception_handler()
  File "F:\virtual\demo\lib\site-packages\rest_framework\views.py", line 298, in get_exception_handler
    return self.settings.EXCEPTION_HANDLER
  File "F:\virtual\demo\lib\site-packages\rest_framework\settings.py", line 220, in __getattr__
    val = perform_import(val, attr)
  File "F:\virtual\demo\lib\site-packages\rest_framework\settings.py", line 166, in perform_import
    return import_from_string(val, setting_name)
  File "F:\virtual\demo\lib\site-packages\rest_framework\settings.py", line 180, in import_from_string
    raise ImportError(msg)
ImportError: Could not import 'drf_day4.exceptions.exception_handler' for API setting 'EXCEPTION_HANDLER'. ModuleNotFoundError: No module named 'drf_day4'.
ERROR 2020-11-05 10:34:02,540 basehttp 124 "GET /home/banner/ HTTP/1.1" 500 233706
ERROR 2020-11-05 10:34:02,540 basehttp 124 "GET /home/header/ HTTP/1.1" 500 233875
ERROR 2020-11-05 10:34:02,602 basehttp 124 "GET /home/footer/ HTTP/1.1" 500 233886
ERROR 2020-11-05 10:34:36,898 exception 118 Internal Server Error: /home/banner/
Traceback (most recent call last):
  File "F:\virtual\demo\lib\site-packages\django\db\backends\utils.py", line 85, in _execute
    return self.cursor.execute(sql, params)
  File "F:\virtual\demo\lib\site-packages\django\db\backends\mysql\base.py", line 71, in execute
    return self.cursor.execute(query, args)
  File "F:\virtual\demo\lib\site-packages\MySQLdb\cursors.py", line 206, in execute
    res = self._query(query)
  File "F:\virtual\demo\lib\site-packages\MySQLdb\cursors.py", line 319, in _query
    db.query(q)
  File "F:\virtual\demo\lib\site-packages\MySQLdb\connections.py", line 259, in query
    _mysql.connection.query(self, query)
MySQLdb._exceptions.OperationalError: (1054, "Unknown column 'banner.id' in 'field list'")

The above exception was the direct cause of the following exception:

Traceback (most recent call last):
  File "F:\virtual\demo\lib\site-packages\django\core\handlers\exception.py", line 35, in inner
    response = get_response(request)
  File "F:\virtual\demo\lib\site-packages\django\core\handlers\base.py", line 128, in _get_response
    response = self.process_exception_by_middleware(e, request)
  File "F:\virtual\demo\lib\site-packages\django\core\handlers\base.py", line 126, in _get_response
    response = wrapped_callback(request, *callback_args, **callback_kwargs)
  File "F:\virtual\demo\lib\site-packages\django\views\decorators\csrf.py", line 54, in wrapped_view
    return view_func(*args, **kwargs)
  File "F:\virtual\demo\lib\site-packages\django\views\generic\base.py", line 69, in view
    return self.dispatch(request, *args, **kwargs)
  File "F:\virtual\demo\lib\site-packages\rest_framework\views.py", line 497, in dispatch
    response = self.handle_exception(exc)
  File "F:\virtual\demo\lib\site-packages\rest_framework\views.py", line 457, in handle_exception
    self.raise_uncaught_exception(exc)
  File "F:\virtual\demo\lib\site-packages\rest_framework\views.py", line 468, in raise_uncaught_exception
    raise exc
  File "F:\virtual\demo\lib\site-packages\rest_framework\views.py", line 494, in dispatch
    response = handler(request, *args, **kwargs)
  File "F:\virtual\demo\lib\site-packages\rest_framework\generics.py", line 199, in get
    return self.list(request, *args, **kwargs)
  File "F:\virtual\demo\lib\site-packages\rest_framework\mixins.py", line 46, in list
    return Response(serializer.data)
  File "F:\virtual\demo\lib\site-packages\rest_framework\serializers.py", line 757, in data
    ret = super().data
  File "F:\virtual\demo\lib\site-packages\rest_framework\serializers.py", line 261, in data
    self._data = self.to_representation(self.instance)
  File "F:\virtual\demo\lib\site-packages\rest_framework\serializers.py", line 675, in to_representation
    self.child.to_representation(item) for item in iterable
  File "F:\virtual\demo\lib\site-packages\django\db\models\query.py", line 272, in __iter__
    self._fetch_all()
  File "F:\virtual\demo\lib\site-packages\django\db\models\query.py", line 1179, in _fetch_all
    self._result_cache = list(self._iterable_class(self))
  File "F:\virtual\demo\lib\site-packages\django\db\models\query.py", line 53, in __iter__
    results = compiler.execute_sql(chunked_fetch=self.chunked_fetch, chunk_size=self.chunk_size)
  File "F:\virtual\demo\lib\site-packages\django\db\models\sql\compiler.py", line 1068, in execute_sql
    cursor.execute(sql, params)
  File "F:\virtual\demo\lib\site-packages\django\db\backends\utils.py", line 100, in execute
    return super().execute(sql, params)
  File "F:\virtual\demo\lib\site-packages\django\db\backends\utils.py", line 68, in execute
    return self._execute_with_wrappers(sql, params, many=False, executor=self._execute)
  File "F:\virtual\demo\lib\site-packages\django\db\backends\utils.py", line 77, in _execute_with_wrappers
    return executor(sql, params, many, context)
  File "F:\virtual\demo\lib\site-packages\django\db\backends\utils.py", line 85, in _execute
    return self.cursor.execute(sql, params)
  File "F:\virtual\demo\lib\site-packages\django\db\utils.py", line 89, in __exit__
    raise dj_exc_value.with_traceback(traceback) from exc_value
  File "F:\virtual\demo\lib\site-packages\django\db\backends\utils.py", line 85, in _execute
    return self.cursor.execute(sql, params)
  File "F:\virtual\demo\lib\site-packages\django\db\backends\mysql\base.py", line 71, in execute
    return self.cursor.execute(query, args)
  File "F:\virtual\demo\lib\site-packages\MySQLdb\cursors.py", line 206, in execute
    res = self._query(query)
  File "F:\virtual\demo\lib\site-packages\MySQLdb\cursors.py", line 319, in _query
    db.query(q)
  File "F:\virtual\demo\lib\site-packages\MySQLdb\connections.py", line 259, in query
    _mysql.connection.query(self, query)
django.db.utils.OperationalError: (1054, "Unknown column 'banner.id' in 'field list'")
ERROR 2020-11-05 10:34:36,900 exception 118 Internal Server Error: /home/header/
Traceback (most recent call last):
  File "F:\virtual\demo\lib\site-packages\django\db\backends\utils.py", line 85, in _execute
    return self.cursor.execute(sql, params)
  File "F:\virtual\demo\lib\site-packages\django\db\backends\mysql\base.py", line 71, in execute
    return self.cursor.execute(query, args)
  File "F:\virtual\demo\lib\site-packages\MySQLdb\cursors.py", line 206, in execute
    res = self._query(query)
  File "F:\virtual\demo\lib\site-packages\MySQLdb\cursors.py", line 319, in _query
    db.query(q)
  File "F:\virtual\demo\lib\site-packages\MySQLdb\connections.py", line 259, in query
    _mysql.connection.query(self, query)
MySQLdb._exceptions.OperationalError: (1054, "Unknown column 'nav.id' in 'field list'")

The above exception was the direct cause of the following exception:

Traceback (most recent call last):
  File "F:\virtual\demo\lib\site-packages\django\core\handlers\exception.py", line 35, in inner
    response = get_response(request)
  File "F:\virtual\demo\lib\site-packages\django\core\handlers\base.py", line 128, in _get_response
    response = self.process_exception_by_middleware(e, request)
  File "F:\virtual\demo\lib\site-packages\django\core\handlers\base.py", line 126, in _get_response
    response = wrapped_callback(request, *callback_args, **callback_kwargs)
  File "F:\virtual\demo\lib\site-packages\django\views\decorators\csrf.py", line 54, in wrapped_view
    return view_func(*args, **kwargs)
  File "F:\virtual\demo\lib\site-packages\django\views\generic\base.py", line 69, in view
    return self.dispatch(request, *args, **kwargs)
  File "F:\virtual\demo\lib\site-packages\rest_framework\views.py", line 497, in dispatch
    response = self.handle_exception(exc)
  File "F:\virtual\demo\lib\site-packages\rest_framework\views.py", line 457, in handle_exception
    self.raise_uncaught_exception(exc)
  File "F:\virtual\demo\lib\site-packages\rest_framework\views.py", line 468, in raise_uncaught_exception
    raise exc
  File "F:\virtual\demo\lib\site-packages\rest_framework\views.py", line 494, in dispatch
    response = handler(request, *args, **kwargs)
  File "F:\virtual\demo\lib\site-packages\rest_framework\generics.py", line 199, in get
    return self.list(request, *args, **kwargs)
  File "F:\virtual\demo\lib\site-packages\rest_framework\mixins.py", line 46, in list
    return Response(serializer.data)
  File "F:\virtual\demo\lib\site-packages\rest_framework\serializers.py", line 757, in data
    ret = super().data
  File "F:\virtual\demo\lib\site-packages\rest_framework\serializers.py", line 261, in data
    self._data = self.to_representation(self.instance)
  File "F:\virtual\demo\lib\site-packages\rest_framework\serializers.py", line 675, in to_representation
    self.child.to_representation(item) for item in iterable
  File "F:\virtual\demo\lib\site-packages\django\db\models\query.py", line 272, in __iter__
    self._fetch_all()
  File "F:\virtual\demo\lib\site-packages\django\db\models\query.py", line 1179, in _fetch_all
    self._result_cache = list(self._iterable_class(self))
  File "F:\virtual\demo\lib\site-packages\django\db\models\query.py", line 53, in __iter__
    results = compiler.execute_sql(chunked_fetch=self.chunked_fetch, chunk_size=self.chunk_size)
  File "F:\virtual\demo\lib\site-packages\django\db\models\sql\compiler.py", line 1068, in execute_sql
    cursor.execute(sql, params)
  File "F:\virtual\demo\lib\site-packages\django\db\backends\utils.py", line 100, in execute
    return super().execute(sql, params)
  File "F:\virtual\demo\lib\site-packages\django\db\backends\utils.py", line 68, in execute
    return self._execute_with_wrappers(sql, params, many=False, executor=self._execute)
  File "F:\virtual\demo\lib\site-packages\django\db\backends\utils.py", line 77, in _execute_with_wrappers
    return executor(sql, params, many, context)
  File "F:\virtual\demo\lib\site-packages\django\db\backends\utils.py", line 85, in _execute
    return self.cursor.execute(sql, params)
  File "F:\virtual\demo\lib\site-packages\django\db\utils.py", line 89, in __exit__
    raise dj_exc_value.with_traceback(traceback) from exc_value
  File "F:\virtual\demo\lib\site-packages\django\db\backends\utils.py", line 85, in _execute
    return self.cursor.execute(sql, params)
  File "F:\virtual\demo\lib\site-packages\django\db\backends\mysql\base.py", line 71, in execute
    return self.cursor.execute(query, args)
  File "F:\virtual\demo\lib\site-packages\MySQLdb\cursors.py", line 206, in execute
    res = self._query(query)
  File "F:\virtual\demo\lib\site-packages\MySQLdb\cursors.py", line 319, in _query
    db.query(q)
  File "F:\virtual\demo\lib\site-packages\MySQLdb\connections.py", line 259, in query
    _mysql.connection.query(self, query)
django.db.utils.OperationalError: (1054, "Unknown column 'nav.id' in 'field list'")
ERROR 2020-11-05 10:34:36,900 exception 118 Internal Server Error: /home/footer/
Traceback (most recent call last):
  File "F:\virtual\demo\lib\site-packages\django\db\backends\utils.py", line 85, in _execute
    return self.cursor.execute(sql, params)
  File "F:\virtual\demo\lib\site-packages\django\db\backends\mysql\base.py", line 71, in execute
    return self.cursor.execute(query, args)
  File "F:\virtual\demo\lib\site-packages\MySQLdb\cursors.py", line 206, in execute
    res = self._query(query)
  File "F:\virtual\demo\lib\site-packages\MySQLdb\cursors.py", line 319, in _query
    db.query(q)
  File "F:\virtual\demo\lib\site-packages\MySQLdb\connections.py", line 259, in query
    _mysql.connection.query(self, query)
MySQLdb._exceptions.OperationalError: (1054, "Unknown column 'nav.id' in 'field list'")

The above exception was the direct cause of the following exception:

Traceback (most recent call last):
  File "F:\virtual\demo\lib\site-packages\django\core\handlers\exception.py", line 35, in inner
    response = get_response(request)
  File "F:\virtual\demo\lib\site-packages\django\core\handlers\base.py", line 128, in _get_response
    response = self.process_exception_by_middleware(e, request)
  File "F:\virtual\demo\lib\site-packages\django\core\handlers\base.py", line 126, in _get_response
    response = wrapped_callback(request, *callback_args, **callback_kwargs)
  File "F:\virtual\demo\lib\site-packages\django\views\decorators\csrf.py", line 54, in wrapped_view
    return view_func(*args, **kwargs)
  File "F:\virtual\demo\lib\site-packages\django\views\generic\base.py", line 69, in view
    return self.dispatch(request, *args, **kwargs)
  File "F:\virtual\demo\lib\site-packages\rest_framework\views.py", line 497, in dispatch
    response = self.handle_exception(exc)
  File "F:\virtual\demo\lib\site-packages\rest_framework\views.py", line 457, in handle_exception
    self.raise_uncaught_exception(exc)
  File "F:\virtual\demo\lib\site-packages\rest_framework\views.py", line 468, in raise_uncaught_exception
    raise exc
  File "F:\virtual\demo\lib\site-packages\rest_framework\views.py", line 494, in dispatch
    response = handler(request, *args, **kwargs)
  File "F:\virtual\demo\lib\site-packages\rest_framework\generics.py", line 199, in get
    return self.list(request, *args, **kwargs)
  File "F:\virtual\demo\lib\site-packages\rest_framework\mixins.py", line 46, in list
    return Response(serializer.data)
  File "F:\virtual\demo\lib\site-packages\rest_framework\serializers.py", line 757, in data
    ret = super().data
  File "F:\virtual\demo\lib\site-packages\rest_framework\serializers.py", line 261, in data
    self._data = self.to_representation(self.instance)
  File "F:\virtual\demo\lib\site-packages\rest_framework\serializers.py", line 675, in to_representation
    self.child.to_representation(item) for item in iterable
  File "F:\virtual\demo\lib\site-packages\django\db\models\query.py", line 272, in __iter__
    self._fetch_all()
  File "F:\virtual\demo\lib\site-packages\django\db\models\query.py", line 1179, in _fetch_all
    self._result_cache = list(self._iterable_class(self))
  File "F:\virtual\demo\lib\site-packages\django\db\models\query.py", line 53, in __iter__
    results = compiler.execute_sql(chunked_fetch=self.chunked_fetch, chunk_size=self.chunk_size)
  File "F:\virtual\demo\lib\site-packages\django\db\models\sql\compiler.py", line 1068, in execute_sql
    cursor.execute(sql, params)
  File "F:\virtual\demo\lib\site-packages\django\db\backends\utils.py", line 100, in execute
    return super().execute(sql, params)
  File "F:\virtual\demo\lib\site-packages\django\db\backends\utils.py", line 68, in execute
    return self._execute_with_wrappers(sql, params, many=False, executor=self._execute)
  File "F:\virtual\demo\lib\site-packages\django\db\backends\utils.py", line 77, in _execute_with_wrappers
    return executor(sql, params, many, context)
  File "F:\virtual\demo\lib\site-packages\django\db\backends\utils.py", line 85, in _execute
    return self.cursor.execute(sql, params)
  File "F:\virtual\demo\lib\site-packages\django\db\utils.py", line 89, in __exit__
    raise dj_exc_value.with_traceback(traceback) from exc_value
  File "F:\virtual\demo\lib\site-packages\django\db\backends\utils.py", line 85, in _execute
    return self.cursor.execute(sql, params)
  File "F:\virtual\demo\lib\site-packages\django\db\backends\mysql\base.py", line 71, in execute
    return self.cursor.execute(query, args)
  File "F:\virtual\demo\lib\site-packages\MySQLdb\cursors.py", line 206, in execute
    res = self._query(query)
  File "F:\virtual\demo\lib\site-packages\MySQLdb\cursors.py", line 319, in _query
    db.query(q)
  File "F:\virtual\demo\lib\site-packages\MySQLdb\connections.py", line 259, in query
    _mysql.connection.query(self, query)
django.db.utils.OperationalError: (1054, "Unknown column 'nav.id' in 'field list'")
ERROR 2020-11-05 10:34:36,985 basehttp 124 "GET /home/header/ HTTP/1.1" 500 22514
ERROR 2020-11-05 10:34:36,992 basehttp 124 "GET /home/banner/ HTTP/1.1" 500 22523
ERROR 2020-11-05 10:34:37,027 basehttp 124 "GET /home/footer/ HTTP/1.1" 500 22514
ERROR 2020-11-05 16:51:27,244 basehttp 124 "GET /admin/user/user/ HTTP/1.1" 500 59
ERROR 2020-11-05 16:51:44,798 basehttp 124 "GET /admin/user/user/ HTTP/1.1" 500 59
ERROR 2020-11-05 19:38:26,187 basehttp 124 "GET /admin/ HTTP/1.1" 500 59
